Workbook

Sheet Parametros
A1: PARÁMETROS DEL MODELO — Método del Coeficiente de Exportación (ECM)
A2: Celdas en AZUL = valores que puedes modificar. Las hojas de cálculo leen estos valores automáticamente.
A4: COEFICIENTES DE EXPORTACIÓN DE NITRÓGENO TOTAL (kg N / ha / año)
A5: Referencia | B5: Fuente | C5: Valor mín | D5: Valor central | E5: Valor máx | F5: Pertinencia | G5: Notas
A6: C01 | B6: Thorburn et al. (2011) — Australia, Burdekin, caña irrigada zona plana | C6: 3 | D6: 5 | E6: 10 | F6: ★★★★★ | G6: Escorrentía superficial sola: 1–5 kg/ha/año. Rango amplio incluye lixiviación.
A7: C02 | B7: Thorburn & Wilkinson (2013) — Australia, Mackay, caña zona plana | C7: 1.5 | D7: 5 | E7: 12 | F7: ★★★★☆ | G7: Diversas prácticas de manejo. Cosecha verde y quema.
A8: C03 | B8: Ghiberto et al. (2009) — Brasil, São Paulo, cosecha verde sin quema | C8: 2 | D8: 5 | E8: 8 | F8: ★★★★☆ | G8: Condición similar al Valle del Cauca desde 2013.
A9: G04 | B9: Waters et al. (2014) — Australia, Gran Barrera de Coral, escala cuenca | C9: 1 | D9: 4 | E9: 8 | F9: ★★★★☆ | G9: Caña + otras coberturas. Escala cuenca grande.
A12: COEFICIENTES DE EXPORTACIÓN DE FÓSFORO TOTAL (kg P / ha / año)
A13: Referencia | B13: Fuente | C13: Valor mín | D13: Valor central | E13: Valor máx | F13: Pertinencia | G13: Notas
A14: C02 | B14: Thorburn & Wilkinson (2013) — Australia, Mackay | C14: 0.1 | D14: 0.4 | E14: 0.8 | F14: ★★★★☆ | G14: Zona plana tropical húmeda.
A15: C03 | B15: Ghiberto et al. (2009) — Brasil, São Paulo | C15: 0.3 | D15: 0.7 | E15: 1.2 | F15: ★★★★☆ | G15: Cosecha verde. Suelos similares (Ultisol/Inceptisol).
A16: C04 | B16: Ghiberto et al. (2011) — Brasil, vinaza | C16: 0.4 | D16: 0.9 | E16: 1.5 | F16: ★★★★☆ | G16: Aplicable en predios con vinaza del Valle del Cauca.
A17: G04 | B17: Waters et al. (2014) — Australia, Gran Barrera Coral | C17: 0.05 | D17: 0.3 | E17: 0.6 | F17: ★★★★☆ | G17: Escala cuenca grande.
A20: VALORES ADOPTADOS PARA EL CÁLCULO — Editar aquí para cambiar todos los resultados
A21: Parámetro | B21: Escenario Bajo | C21: Escenario Medio (valor central) | D21: Escenario Alto | E21: Unidad | F21: Referencias usadas
A22: Nitrógeno Total (N) | B22: 3 | C22: =ROUND(AVERAGE(D6:D9),1) -> 4.8 | D22: 10 | E22: kg N/ha/año | F22: C01, C02, C03, G04 — rango consenso para caña zona plana tropical
A23: Fósforo Total (P) | B23: 0.1 | C23: =ROUND(AVERAGE(D14:D17),1) -> 0.6 | D23: 1.5 | E23: kg P/ha/año | F23: C02, C03, C04, G04 — rango consenso para caña zona plana tropical

Sheet Estimacion ECM
A1: ESTIMACIÓN DE CARGA DIFUSA — Método del Coeficiente de Exportación (ECM) |Año de referencia: 2021
A2: Fórmula: Carga (kg/año) = Área caña (ha) × Coeficiente (kg/ha/año)
A3: IDENTIFICACIÓN | D3: CARGA N TOTAL (kg N/año) | G3: CARGA P TOTAL (kg P/año) | J3: CARGA N TOTAL (kg N/día) | M3: CARGA P TOTAL (kg P/día)
A4: Río | B4: Área caña (ha) | C4: Fuente área | D4: N Mínimo (kg/año) | E4: N Promedio (kg/año) | F4: N Máximo (kg/año) | G4: P Mínimo | H4: P Promedio | I4: P Máximo | J4: N Mín (kg/día) | K4: N Promedio (kg/día) | L4: N Máximo (kg/día) | M4: P Mín (kg/día) | N4: P Promedio (kg/día) | O4: P Máximo (kg/día)
A5: Rio Cauca | B5: 23225.56 | C5: CVC/IGAC 2017 | D5: =IF(ISNUMBER(B5),B5*Parametros!$B$22,"—") -> 69676.68 | E5: =IF(ISNUMBER(B5),B5*Parametros!$C$22,"—") -> 111482.69 | F5: =IF(ISNUMBER(B5),B5*Parametros!$D$22,"—") -> 232255.6 | G5: =IF(ISNUMBER(B5),B5*Parametros!$B$23,"—") -> 2322.556 | H5: =IF(ISNUMBER(B5),B5*Parametros!$C$23,"—") -> 13935.336 | I5: =IF(ISNUMBER(B5),B5*Parametros!$D$23,"—") -> 34838.34 | J5: =IF(ISNUMBER(B5),B5*Parametros!$B$22/365,"—") -> 190.89501 | K5: =IF(ISNUMBER(B5),B5*Parametros!$C$22/365,"—") -> 305.43202 | L5: =IF(ISNUMBER(B5),B5*Parametros!$D$22/365,"—") -> 636.31671 | M5: =IF(ISNUMBER(B5),B5*Parametros!$B$23/365,"—") -> 6.3631671 | N5: =IF(ISNUMBER(B5),B5*Parametros!$C$23/365,"—") -> 38.179003 | O5: =IF(ISNUMBER(B5),B5*Parametros!$D$23/365,"—") -> 95.447507
A6: Rio Amaime | B6: 3475.86 | C6: CVC/IGAC 2017 | D6: =IF(ISNUMBER(B6),B6*Parametros!$B$22,"—") -> 10427.58 | E6: =IF(ISNUMBER(B6),B6*Parametros!$C$22,"—") -> 16684.128 | F6: =IF(ISNUMBER(B6),B6*Parametros!$D$22,"—") -> 34758.6 | G6: =IF(ISNUMBER(B6),B6*Parametros!$B$23,"—") -> 347.586 | H6: =IF(ISNUMBER(B6),B6*Parametros!$C$23,"—") -> 2085.516 | I6: =IF(ISNUMBER(B6),B6*Parametros!$D$23,"—") -> 5213.79 | J6: =IF(ISNUMBER(B6),B6*Parametros!$B$22/365,"—") -> 28.568712 | K6: =IF(ISNUMBER(B6),B6*Parametros!$C$22/365,"—") -> 45.70994 | L6: =IF(ISNUMBER(B6),B6*Parametros!$D$22/365,"—") -> 95.229041 | M6: =IF(ISNUMBER(B6),B6*Parametros!$B$23/365,"—") -> 0.95229041 | N6: =IF(ISNUMBER(B6),B6*Parametros!$C$23/365,"—") -> 5.7137425 | O6: =IF(ISNUMBER(B6),B6*Parametros!$D$23/365,"—") -> 14.284356
A7: Rio Bolo | B7: 3794.85 | C7: CVC/IGAC 2017 | D7: =IF(ISNUMBER(B7),B7*Parametros!$B$22,"—") -> 11384.55 | E7: =IF(ISNUMBER(B7),B7*Parametros!$C$22,"—") -> 18215.28 | F7: =IF(ISNUMBER(B7),B7*Parametros!$D$22,"—") -> 37948.5 | G7: =IF(ISNUMBER(B7),B7*Parametros!$B$23,"—") -> 379.485 | H7: =IF(ISNUMBER(B7),B7*Parametros!$C$23,"—") -> 2276.91 | I7: =IF(ISNUMBER(B7),B7*Parametros!$D$23,"—") -> 5692.275 | J7: =IF(ISNUMBER(B7),B7*Parametros!$B$22/365,"—") -> 31.190548 | K7: =IF(ISNUMBER(B7),B7*Parametros!$C$22/365,"—") -> 49.904877 | L7: =IF(ISNUMBER(B7),B7*Parametros!$D$22/365,"—") -> 103.96849 | M7: =IF(ISNUMBER(B7),B7*Parametros!$B$23/365,"—") -> 1.0396849 | N7: =IF(ISNUMBER(B7),B7*Parametros!$C$23/365,"—") -> 6.2381096 | O7: =IF(ISNUMBER(B7),B7*Parametros!$D$23/365,"—") -> 15.595274
A8: Rio Bugalagrande | B8: 1282.58 | C8: CVC/IGAC 2017 | D8: =IF(ISNUMBER(B8),B8*Parametros!$B$22,"—") -> 3847.74 | E8: =IF(ISNUMBER(B8),B8*Parametros!$C$22,"—") -> 6156.384 | F8: =IF(ISNUMBER(B8),B8*Parametros!$D$22,"—") -> 12825.8 | G8: =IF(ISNUMBER(B8),B8*Parametros!$B$23,"—") -> 128.258 | H8: =IF(ISNUMBER(B8),B8*Parametros!$C$23,"—") -> 769.548 | I8: =IF(ISNUMBER(B8),B8*Parametros!$D$23,"—") -> 1923.87 | J8: =IF(ISNUMBER(B8),B8*Parametros!$B$22/365,"—") -> 10.541753 | K8: =IF(ISNUMBER(B8),B8*Parametros!$C$22/365,"—") -> 16.866805 | L8: =IF(ISNUMBER(B8),B8*Parametros!$D$22/365,"—") -> 35.139178 | M8: =IF(ISNUMBER(B8),B8*Parametros!$B$23/365,"—") -> 0.35139178 | N8: =IF(ISNUMBER(B8),B8*Parametros!$C$23/365,"—") -> 2.1083507 | O8: =IF(ISNUMBER(B8),B8*Parametros!$D$23/365,"—") -> 5.2708767
A9: Rio Desbaratado | B9: 1613.65 | C9: CVC/IGAC 2017 | D9: =IF(ISNUMBER(B9),B9*Parametros!$B$22,"—") -> 4840.95 | E9: =IF(ISNUMBER(B9),B9*Parametros!$C$22,"—") -> 7745.52 | F9: =IF(ISNUMBER(B9),B9*Parametros!$D$22,"—") -> 16136.5 | G9: =IF(ISNUMBER(B9),B9*Parametros!$B$23,"—") -> 161.365 | H9: =IF(ISNUMBER(B9),B9*Parametros!$C$23,"—") -> 968.19 | I9: =IF(ISNUMBER(B9),B9*Parametros!$D$23,"—") -> 2420.475 | J9: =IF(ISNUMBER(B9),B9*Parametros!$B$22/365,"—") -> 13.262877 | K9: =IF(ISNUMBER(B9),B9*Parametros!$C$22/365,"—") -> 21.220603 | L9: =IF(ISNUMBER(B9),B9*Parametros!$D$22/365,"—") -> 44.209589 | M9: =IF(ISNUMBER(B9),B9*Parametros!$B$23/365,"—") -> 0.44209589 | N9: =IF(ISNUMBER(B9),B9*Parametros!$C$23/365,"—") -> 2.6525753 | O9: =IF(ISNUMBER(B9),B9*Parametros!$D$23/365,"—") -> 6.6314384
A10: Rio Fraile | B10: 4990 | C10: CVC/IGAC 2017 | D10: =IF(ISNUMBER(B10),B10*Parametros!$B$22,"—") -> 14970 | E10: =IF(ISNUMBER(B10),B10*Parametros!$C$22,"—") -> 23952 | F10: =IF(ISNUMBER(B10),B10*Parametros!$D$22,"—") -> 49900 | G10: =IF(ISNUMBER(B10),B10*Parametros!$B$23,"—") -> 499 | H10: =IF(ISNUMBER(B10),B10*Parametros!$C$23,"—") -> 2994 | I10: =IF(ISNUMBER(B10),B10*Parametros!$D$23,"—") -> 7485 | J10: =IF(ISNUMBER(B10),B10*Parametros!$B$22/365,"—") -> 41.013699 | K10: =IF(ISNUMBER(B10),B10*Parametros!$C$22/365,"—") -> 65.621918 | L10: =IF(ISNUMBER(B10),B10*Parametros!$D$22/365,"—") -> 136.71233 | M10: =IF(ISNUMBER(B10),B10*Parametros!$B$23/365,"—") -> 1.3671233 | N10: =IF(ISNUMBER(B10),B10*Parametros!$C$23/365,"—") -> 8.2027397 | O10: =IF(ISNUMBER(B10),B10*Parametros!$D$23/365,"—") -> 20.506849
A11: Rio Guabas | B11: 1825.85 | C11: CVC/IGAC 2017 | D11: =IF(ISNUMBER(B11),B11*Parametros!$B$22,"—") -> 5477.55 | E11: =IF(ISNUMBER(B11),B11*Parametros!$C$22,"—") -> 8764.08 | F11: =IF(ISNUMBER(B11),B11*Parametros!$D$22,"—") -> 18258.5 | G11: =IF(ISNUMBER(B11),B11*Parametros!$B$23,"—") -> 182.585 | H11: =IF(ISNUMBER(B11),B11*Parametros!$C$23,"—") -> 1095.51 | I11: =IF(ISNUMBER(B11),B11*Parametros!$D$23,"—") -> 2738.775 | J11: =IF(ISNUMBER(B11),B11*Parametros!$B$22/365,"—") -> 15.006986 | K11: =IF(ISNUMBER(B11),B11*Parametros!$C$22/365,"—") -> 24.011178 | L11: =IF(ISNUMBER(B11),B11*Parametros!$D$22/365,"—") -> 50.023288 | M11: =IF(ISNUMBER(B11),B11*Parametros!$B$23/365,"—") -> 0.50023288 | N11: =IF(ISNUMBER(B11),B11*Parametros!$C$23/365,"—") -> 3.0013973 | O11: =IF(ISNUMBER(B11),B11*Parametros!$D$23/365,"—") -> 7.5034932
A12: Rio Guadalajara | B12: 654.74 | C12: CVC/IGAC 2017 | D12: =IF(ISNUMBER(B12),B12*Parametros!$B$22,"—") -> 1964.22 | E12: =IF(ISNUMBER(B12),B12*Parametros!$C$22,"—") -> 3142.752 | F12: =IF(ISNUMBER(B12),B12*Parametros!$D$22,"—") -> 6547.4 | G12: =IF(ISNUMBER(B12),B12*Parametros!$B$23,"—") -> 65.474 | H12: =IF(ISNUMBER(B12),B12*Parametros!$C$23,"—") -> 392.844 | I12: =IF(ISNUMBER(B12),B12*Parametros!$D$23,"—") -> 982.11 | J12: =IF(ISNUMBER(B12),B12*Parametros!$B$22/365,"—") -> 5.3814247 | K12: =IF(ISNUMBER(B12),B12*Parametros!$C$22/365,"—") -> 8.6102795 | L12: =IF(ISNUMBER(B12),B12*Parametros!$D$22/365,"—") -> 17.938082 | M12: =IF(ISNUMBER(B12),B12*Parametros!$B$23/365,"—") -> 0.17938082 | N12: =IF(ISNUMBER(B12),B12*Parametros!$C$23/365,"—") -> 1.0762849 | O12: =IF(ISNUMBER(B12),B12*Parametros!$D$23/365,"—") -> 2.6907123
A13: Rio Guachal | B13: 266.9 | C13: CVC/IGAC 2017 | D13: =IF(ISNUMBER(B13),B13*Parametros!$B$22,"—") -> 800.7 | E13: =IF(ISNUMBER(B13),B13*Parametros!$C$22,"—") -> 1281.12 | F13: =IF(ISNUMBER(B13),B13*Parametros!$D$22,"—") -> 2669 | G13: =IF(ISNUMBER(B13),B13*Parametros!$B$23,"—") -> 26.69 | H13: =IF(ISNUMBER(B13),B13*Parametros!$C$23,"—") -> 160.14 | I13: =IF(ISNUMBER(B13),B13*Parametros!$D$23,"—") -> 400.35 | J13: =IF(ISNUMBER(B13),B13*Parametros!$B$22/365,"—") -> 2.1936986 | K13: =IF(ISNUMBER(B13),B13*Parametros!$C$22/365,"—") -> 3.5099178 | L13: =IF(ISNUMBER(B13),B13*Parametros!$D$22/365,"—") -> 7.3123288 | M13: =IF(ISNUMBER(B13),B13*Parametros!$B$23/365,"—") -> 0.073123288 | N13: =IF(ISNUMBER(B13),B13*Parametros!$C$23/365,"—") -> 0.43873973 | O13: =IF(ISNUMBER(B13),B13*Parametros!$D$23/365,"—") -> 1.0968493
A14: Rio La Paila | B14: 1438.91 | C14: CVC/IGAC 2017 | D14: =IF(ISNUMBER(B14),B14*Parametros!$B$22,"—") -> 4316.73 | E14: =IF(ISNUMBER(B14),B14*Parametros!$C$22,"—") -> 6906.768 | F14: =IF(ISNUMBER(B14),B14*Parametros!$D$22,"—") -> 14389.1 | G14: =IF(ISNUMBER(B14),B14*Parametros!$B$23,"—") -> 143.891 | H14: =IF(ISNUMBER(B14),B14*Parametros!$C$23,"—") -> 863.346 | I14: =IF(ISNUMBER(B14),B14*Parametros!$D$23,"—") -> 2158.365 | J14: =IF(ISNUMBER(B14),B14*Parametros!$B$22/365,"—") -> 11.826658 | K14: =IF(ISNUMBER(B14),B14*Parametros!$C$22/365,"—") -> 18.922652 | L14: =IF(ISNUMBER(B14),B14*Parametros!$D$22/365,"—") -> 39.422192 | M14: =IF(ISNUMBER(B14),B14*Parametros!$B$23/365,"—") -> 0.39422192 | N14: =IF(ISNUMBER(B14),B14*Parametros!$C$23/365,"—") -> 2.3653315 | O14: =IF(ISNUMBER(B14),B14*Parametros!$D$23/365,"—") -> 5.9133288
A15: Rio Nima | B15: 896.63 | C15: CVC/IGAC 2017 | D15: =IF(ISNUMBER(B15),B15*Parametros!$B$22,"—") -> 2689.89 | E15: =IF(ISNUMBER(B15),B15*Parametros!$C$22,"—") -> 4303.824 | F15: =IF(ISNUMBER(B15),B15*Parametros!$D$22,"—") -> 8966.3 | G15: =IF(ISNUMBER(B15),B15*Parametros!$B$23,"—") -> 89.663 | H15: =IF(ISNUMBER(B15),B15*Parametros!$C$23,"—") -> 537.978 | I15: =IF(ISNUMBER(B15),B15*Parametros!$D$23,"—") -> 1344.945 | J15: =IF(ISNUMBER(B15),B15*Parametros!$B$22/365,"—") -> 7.3695616 | K15: =IF(ISNUMBER(B15),B15*Parametros!$C$22/365,"—") -> 11.791299 | L15: =IF(ISNUMBER(B15),B15*Parametros!$D$22/365,"—") -> 24.565205 | M15: =IF(ISNUMBER(B15),B15*Parametros!$B$23/365,"—") -> 0.24565205 | N15: =IF(ISNUMBER(B15),B15*Parametros!$C$23/365,"—") -> 1.4739123 | O15: =IF(ISNUMBER(B15),B15*Parametros!$D$23/365,"—") -> 3.6847808
A16: Rio Palo | B16: 511.13 | C16: CRC 2014 | D16: =IF(ISNUMBER(B16),B16*Parametros!$B$22,"—") -> 1533.39 | E16: =IF(ISNUMBER(B16),B16*Parametros!$C$22,"—") -> 2453.424 | F16: =IF(ISNUMBER(B16),B16*Parametros!$D$22,"—") -> 5111.3 | G16: =IF(ISNUMBER(B16),B16*Parametros!$B$23,"—") -> 51.113 | H16: =IF(ISNUMBER(B16),B16*Parametros!$C$23,"—") -> 306.678 | I16: =IF(ISNUMBER(B16),B16*Parametros!$D$23,"—") -> 766.695 | J16: =IF(ISNUMBER(B16),B16*Parametros!$B$22/365,"—") -> 4.2010685 | K16: =IF(ISNUMBER(B16),B16*Parametros!$C$22/365,"—") -> 6.7217096 | L16: =IF(ISNUMBER(B16),B16*Parametros!$D$22/365,"—") -> 14.003562 | M16: =IF(ISNUMBER(B16),B16*Parametros!$B$23/365,"—") -> 0.14003562 | N16: =IF(ISNUMBER(B16),B16*Parametros!$C$23/365,"—") -> 0.8402137 | O16: =IF(ISNUMBER(B16),B16*Parametros!$D$23/365,"—") -> 2.1005342
... A20: Rio Zabaletas | B20: 2526.97 | C20: CVC/IGAC 2017 | D20: =IF(ISNUMBER(B20),B20*Parametros!$B$22,"—") -> 7580.91 | E20: =IF(ISNUMBER(B20),B20*Parametros!$C$22,"—") -> 12129.456 | F20: =IF(ISNUMBER(B20),B20*Parametros!$D$22,"—") -> 25269.7 | G20: =IF(ISNUMBER(B20),B20*Parametros!$B$23,"—") -> 252.697 | H20: =IF(ISNUMBER(B20),B20*Parametros!$C$23,"—") -> 1516.182 | I20: =IF(ISNUMBER(B20),B20*Parametros!$D$23,"—") -> 3790.455 | J20: =IF(ISNUMBER(B20),B20*Parametros!$B$22/365,"—") -> 20.769616 | K20: =IF(ISNUMBER(B20),B20*Parametros!$C$22/365,"—") -> 33.231386 | L20: =IF(ISNUMBER(B20),B20*Parametros!$D$22/365,"—") -> 69.232055 | M20: =IF(ISNUMBER(B20),B20*Parametros!$B$23/365,"—") -> 0.69232055 | N20: =IF(ISNUMBER(B20),B20*Parametros!$C$23/365,"—") -> 4.1539233 | O20: =IF(ISNUMBER(B20),B20*Parametros!$D$23/365,"—") -> 10.384808
A21: TOTAL | B21: =SUM(B5:B20) -> 48318.11 | D21: =SUM(D5:D20) -> 144954.33 | E21: =SUM(E5:E20) -> 231926.93 | F21: =SUM(F5:F20) -> 483181.1 | G21: =SUM(G5:G20) -> 4831.811 | H21: =SUM(H5:H20) -> 28990.866 | I21: =SUM(I5:I20) -> 72477.165 | J21: =SUM(J5:J20) -> 397.13515 | K21: =SUM(K5:K20) -> 635.41624 | ... O21: =SUM(O5:O20) -> 198.56758
A23: ★ = Escenario central recomendado para el informe. Escenario Mínimo y Máximo definen el rango de incertidumbre. Rio Cauca (buffer directo, 27.881 ha) no se incluye — su tratamiento metodológico está pendiente de definición. Rio Risaralda sin dato de área — completar cuando esté disponible.

Sheet Estadísticas Factores
A1: CARACTERIZACIÓN ESTADÍSTICA DE FACTORES DE EMISIÓN — ECM Contaminación Difusa
A3: Tabla 1 — Valores reportados por referencia bibliográfica
A4: N mín (kg N/ha/año) | B4: N central (kg N/ha/año) | C4: N máx (kg N/ha/año) | D4: P mín (kg P/ha/año) | E4: P central (kg P/ha/año) | F4: P máx (kg P/ha/año)
A5: 3 | B5: 5 | C5: 10 | D5: 0.1 | E5: 0.4 | F5: 0.8
A6: 1.5 | B6: 5 | C6: 12 | D6: 0.3 | E6: 0.7 | F6: 1.2
A7: 2 | B7: 5 | C7: 8 | D7: 0.4 | E7: 0.9 | F7: 1.5
A8: 1 | B8: 4 | C8: 8 | D8: 0.05 | E8: 0.3 | F8: 0.6
A12: Tabla 2 — Estadísticas sobre los valores centrales
A13: Estadístico | B13: N Total (kg N/ha/año) | C13: P Total (kg P/ha/año) | D13: Interpretación
A14: Número de referencias | B14: =COUNT(B5,B6,B7,B8) -> 4 | C14: =COUNT(E5,E6,E7,E8) -> 4 | D14: Número de referencias con valor central disponible.
A15: Media | B15: =AVERAGE(B5,B6,B7,B8) -> 4.75 | C15: =AVERAGE(E5,E6,E7,E8) -> 0.575 | D15: Valor adoptado N=4.8 difiere <1% de la media. Valor adoptado P=0.6 difiere <5%.
A16: Mediana | B16: =MEDIAN(B5,B6,B7,B8) -> 5 | C16: =MEDIAN(E5,E6,E7,E8) -> 0.55 | D16: Casi igual a la media, lo que indica que no hay ningún estudio que esté inflando o jalando los resultados hacia un extremo. Los valores entre referencias son consistentes.
A17: Desviación estándar (σ) | B17: =STDEV(B5,B6,B7,B8) -> 0.5 | C17: =STDEV(E5,E6,E7,E8) -> 0.27537853 | D17: Para N es muy baja (σ=0,50): las cuatro referencias están de acuerdo. Para P es moderada (σ=0,28): hay variación real entre estudios, que se explica porque el fósforo depende mucho del tipo de suelo, y los sitios de referencia tienen suelos distintos entre sí y distintos a los del Valle del Cauca.
A18: Coeficiente de variación (CV%) | B18: =STDEV(B5,B6,B7,B8)/AVERAGE(B5,B6,B7,B8) -> 0.10526316 | C18: =STDEV(E5,E6,E7,E8)/AVERAGE(E5,E6,E7,E8) -> 0.47891918 | D18: N con 10,5% indica que el coeficiente de nitrógeno es confiable — los estudios dicen prácticamente lo mismo. P con 47,9% indica que hay incertidumbre real, por eso para el fósforo es más importante trabajar con los tres escenarios (mín, central, máx) que para el nitrógeno.
A19: Límite inferior IC 95% (x̄ − 2σ) | B19: =AVERAGE(B5,B6,B7,B8)-2*STDEV(B5,B6,B7,B8) -> 3.75 | C19: =AVERAGE(E5,E6,E7,E8)-2*STDEV(E5,E6,E7,E8) -> 0.024242945 | D19: Por debajo de este valor los coeficientes no tendrían respaldo estadístico en la literatura. Sirve como referencia del piso del rango aceptable.
A20: Límite superior IC 95% (x̄ − 2σ) | B20: =AVERAGE(B5,B6,B7,B8)+2*STDEV(B5,B6,B7,B8) -> 5.75 | C20: =AVERAGE(E5,E6,E7,E8)+2*STDEV(E5,E6,E7,E8) -> 1.1257571 | D20: Los valores adoptados (N=4,8 y P=0,6) quedan dentro del intervalo. Esto confirma formalmente que la elección de coeficientes es coherente con lo que reporta la bibliografía.

Sheet Series_Historicas
A1: Series históricas de calidad de agua — estaciones de los ríos tributarios
A2: Estadísticos calculados sobre el registro histórico de la red de monitoreo de la CVC. Los valores reportados por el laboratorio como "< LC" se contabilizaron con el límite de cuantificación completo. Los nombres de estación se consolidaron unificando variantes de mayúsculas y tildes.
A4: Río | B4: Estación | C4: n | D4: N-Tot mín | E4: N-Tot prom | F4: N-Tot máx | G4: n | H4: P-Tot mín | I4: P-Tot prom | J4: P-Tot máx | K4: Período
A5: Bolo | B5: Rio Bolo - puente Pradera - Palmira | C5: 6 | D5: 0.5 | E5: 1.11 | F5: 2.45 | G5: 16 | H5: 0.066 | I5: 0.108 | J5: 0.186 | K5: 2016–2025
A6: Bolo | B6: Rio Bolo - puente Bolo - San Isidro - vía a Candelaria | C6: 6 | D6: 0.905 | E6: 3.089 | F6: 6.6 | G6: 16 | H6: 0.066 | I6: 0.148 | J6: 0.379 | K6: 2016–2025
A7: Bolo | B7: Rio Bolo - antes desembocadura a Frayle en puente Recta Cali - Palmira | C7: 6 | D7: 0.944 | E7: 3.014 | F7: 5.52 | G7: 16 | H7: 0.095 | I7: 0.286 | J7: 0.69 | K7: 2016–2025
A8: Bolo | B8: Rio Bolo - limnígrafo CVC - Los Minchos | C8: 6 | D8: 0.381 | E8: 0.931 | F8: 2.15 | G8: 15 | H8: 0.051 | I8: 0.084 | J8: 0.124 | K8: 2016–2025
A9: Fraile | B9: Rio Frayle - Nacimiento El Pedregal | C9: 6 | D9: 0.394 | E9: 1.048 | F9: 2.14 | G9: 16 | H9: 0.051 | I9: 0.086 | J9: 0.11 | K9: 2016–2025
A10: Fraile | B10: Rio Frayle - puente Vía a Miranda | C10: 6 | D10: 0.843 | E10: 4.389 | F10: 11.3 | G10: 16 | H10: 0.051 | I10: 0.286 | J10: 1.36 | K10: 2016–2025
A11: Fraile | B11: Rio Frayle - limnigrafo CVC - caserio Brisas de Frayle | C11: 6 | D11: 0.9 | E11: 2.187 | F11: 4.11 | G11: 16 | H11: 0.095 | I11: 0.223 | J11: 0.982 | K11: 2016–2025
A12: Fraile | B12: Rio Frayle - antes Desembocadura a rio Guachal Recta Cali Palmira | C12: 6 | D12: 2.21 | E12: 3.193 | F12: 4.42 | G12: 15 | H12: 0.095 | I12: 0.411 | J12: 1.11 | K12: 2016–2025
A13: Guachal | B13: GG3 - Rio Guachal - Antes Desembocadura a Rio Cauca | C13: 5 | D13: 2.36 | E13: 2.808 | F13: 3.4 | G13: 16 | H13: 0.096 | I13: 0.396 | J13: 0.754 | K13: 2016–2025
A14: Párraga | B14: Rio Parraga - puente via Florida - Pradera | C14: 1 | D14: 4.77 | E14: 4.77 | F14: 4.77 | G14: 5 | H14: 0.066 | I14: 0.316 | J14: 0.531 | K14: 2016–2018
A15: Párraga | B15: Rio Parraga - puente vía Candelaria - Florida | C15: 1 | D15: 7.54 | E15: 7.54 | F15: 7.54 | G15: 5 | H15: 0.221 | I15: 0.618 | J15: 0.957 | K15: 2016–2018
A16: Párraga | B16: Rio Parraga - antes Desembocadura a rio Frayle | C16: 1 | D16: 4.98 | E16: 4.98 | F16: 4.98 | G16: 5 | H16: 0.317 | I16: 0.675 | J16: 1.28 | K16: 2016–2018
... A24: Palo | B24: Bocatoma corregimiento El Palo | C24: 8 | D24: 0.5 | E24: 0.64 | F24: 1.1 | G24: 9 | H24: 0.1 | I24: 0.411 | J24: 1.44 | K24: 2017–2025
A25: Palo | B25: Antes Bocatoma Propal | C25: 0 | G25: 0 | K25: 2010–2012
A26: Desbaratado | B26: Antes de bocatoma cabecera Miranda | C26: 9 | D26: 0.5 | E26: 0.513 | F26: 0.6 | G26: 11 | H26: 0.1 | I26: 0.168 | J26: 0.64 | K26: 2019–2026
A27: Desbaratado | B27: Antes de porcícola (Pte. Jordán) | C27: 9 | D27: 0.5 | E27: 0.523 | F27: 0.7 | G27: 11 | H27: 0.1 | I27: 0.194 | J27: 0.37 | K27: 2019–2026
A28: Desbaratado | B28: Puente Ortigal | C28: 9 | D28: 0.5 | E28: 0.708 | F28: 1.8 | G28: 11 | H28: 0.1 | I28: 0.333 | J28: 1.73 | K28: 2019–2026
A29: Amaime | B29: Rio Amaime - antes Caserio el Placer | C29: 8 | D29: 0.366 | E29: 1.195 | F29: 3.4 | G29: 19 | H29: 0.051 | I29: 0.146 | J29: 1.13 | K29: 2016–2025
A30: Amaime | B30: Rio Amaime - antes desembocadura de Rio Nima | C30: 7 | D30: 0.805 | E30: 1.687 | F30: 3.78 | G30: 19 | H30: 0.051 | I30: 0.275 | J30: 1.7 | K30: 2016–2025
A31: Amaime | B31: Rio Amaime - antes Desembocadura a Rio Cauca | C31: 7 | D31: 0.866 | E31: 1.677 | F31: 3.72 | G31: 19 | H31: 0.051 | I31: 0.216 | J31: 0.792 | K31: 2016–2025
A32: Amaime | B32: Rio Amaime - antes Caserio Tablones - Balneario Puerto Amor | C32: 6 | D32: 0.486 | E32: 1.107 | F32: 2.24 | G32: 18 | H32: 0.051 | I32: 0.088 | J32: 0.174 | K32: 2016–2025
A33: Amaime | B33: Rio Amaime - despues Caserio Auji | C33: 3 | D33: 0.5 | E33: 1.228 | F33: 2.47 | G33: 15 | H33: 0.051 | I33: 0.084 | J33: 0.117 | K33: 2016–2023
A34: Nima | B34: Rio Nima - Acueducto Nima | C34: 8 | D34: 0.52 | E34: 1.238 | F34: 3.2 | G34: 18 | H34: 0.051 | I34: 0.091 | J34: 0.164 | K34: 2016–2025
A35: Nima | B35: Rio Nima - antes desembocadura a rio Amaime | C35: 7 | D35: 1.2 | E35: 2.971 | F35: 7.87 | G35: 18 | H35: 0.051 | I35: 0.427 | J35: 1.89 | K35: 2016–2025
A36: Nima | B36: Rio Nima - antes Caserio de tenjo | C36: 7 | D36: 0.683 | E36: 1.305 | F36: 3.03 | G36: 17 | H36: 0.051 | I36: 0.138 | J36: 0.802 | K36: 2016–2025
A37: Guabas | B37: Rio Guabas - Quebrada Los Lulos - antes desembocadura a rio Guabas | C37: 7 | D37: 0.488 | E37: 0.922 | F37: 1.76 | G37: 17 | H37: 0.051 | I37: 0.089 | J37: 0.128 | K37: 2016–2025
... A47: Zabaletas | B47: Rio Sabaletas - antes desembocadura a Rio Cauca | C47: 8 | D47: 1.23 | E47: 2.464 | F47: 3.42 | G47: 16 | H47: 0.095 | I47: 0.27 | J47: 0.435 | K47: 2017–2025
A48: Zabaletas | B48: Río Sabaletas - Puente después caserío Los Medios | C48: 0 | G48: 2 | H48: 0.051 | I48: 0.111 | J48: 0.171 | K48: 2017–2017
A49: Guadalajara | B49: Rio Guadalajara - La Piscina - Vía a Alaska | C49: 6 | D49: 0.463 | E49: 0.886 | F49: 1.61 | G49: 19 | H49: 0.051 | I49: 0.082 | J49: 0.096 | K49: 2016–2025
A50: Guadalajara | B50: Rio Guadalajara - Antes desembocadura de Quebrada La Magdalena - puente Colgante | C50: 6 | D50: 0.463 | E50: 0.839 | F50: 1.57 | G50: 19 | H50: 0.051 | I50: 0.081 | J50: 0.11 | K50: 2016–2025
A51: Guadalajara | B51: Rio Guadalajara - Puente Balneario los Guaduales | C51: 6 | D51: 0.463 | E51: 0.899 | F51: 1.71 | G51: 19 | H51: 0.051 | I51: 0.088 | J51: 0.211 | K51: 2016–2025
A52: Guadalajara | B52: Rio Guadalajara - Bocatoma Acueducto Buga | C52: 6 | D52: 0.366 | E52: 0.688 | F52: 0.9 | G52: 19 | H52: 0.051 | I52: 0.082 | J52: 0.096 | K52: 2016–2025
A53: Guadalajara | B53: Rio Guadalajara - puente Frente vía Ferrea | C53: 6 | D53: 0.498 | E53: 1.166 | F53: 2.55 | G53: 19 | H53: 0.051 | I53: 0.284 | J53: 3.36 | K53: 2016–2025
A54: Guadalajara | B54: Rio Guadalajara - antes desembocadura a Rio Cauca (El Porvenir) | C54: 6 | D54: 0.925 | E54: 2.764 | F54: 8.46 | G54: 19 | H54: 0.051 | I54: 0.187 | J54: 1.12 | K54: 2016–2025
A55: Riofrío | B55: Rio Riofrio - Rio Guayabal | C55: 5 | D55: 0.438 | E55: 0.702 | F55: 1.4 | G55: 18 | H55: 0.051 | I55: 0.09 | J55: 0.251 | K55: 2016–2025
A56: Riofrío | B56: Rio Riofrio - puente despues Salonica - limnigrafo CVC | C56: 5 | D56: 0.463 | E56: 0.835 | F56: 1.7 | G56: 18 | H56: 0.051 | I56: 0.084 | J56: 0.113 | K56: 2016–2025
A57: Riofrío | B57: Rio Riofrio - Bocatoma Acueducto de Riofrio | C57: 6 | D57: 0.25 | E57: 0.669 | F57: 1.7 | G57: 18 | H57: 0.051 | I57: 0.101 | J57: 0.397 | K57: 2016–2025
...

Sheet Correlacion
A1: Influencia de la caña de azúcar sobre la calidad del agua de los tributarios
A2: Para cada tramo se acumula el área de caña de azúcar situada aguas arriba de su estación de cierre y se convierte en carga anual de nitrógeno y fósforo (área × factor de emisión). Esa carga acumulada se contrasta con TODAS las mediciones individuales de la estación, no con tres estadísticos resumidos: la regresión de cada río usa entre 16 y 70 datos reales. La pendiente indica cuánto varía la concentración observada por cada kilogramo/año adicional de carga de caña aguas arriba; el R² indica qué parte de la variabilidad observada queda explicada por esa carga. Las gráficas a la derecha muestran la nube de puntos y la recta ajustada de cada río.
A4: Factores de emisión adoptados (kg/ha/año), enlazados a la hoja Parametros — N: 3,0 / 4,8 / 10,0 · P: 0,1 / 0,6 / 1,5 (mínimo / promedio / máximo). La regresión usa el escenario promedio.
A6: RESUMEN — ¿cuánto de la calidad observada se asocia a la caña aguas arriba?
A7: Río | B7: Tramos | C7: Área caña (ha) | D7: n datos N | E7: Pendiente N | F7: R² N | G7: n datos P | H7: Pendiente P | I7: R² P | J7: Lectura
A8: Bolo | B8: 3 | C8: 3794.8 | D8: =B33 -> 18 | E8: =C33 -> 0.00010974651 | F8: =D33 -> 0.15367841 | G8: =B34 -> 48 | H8: =C34 -> 8.5681694e-05 | I8: =D34 -> 0.3096169 | J8: =IF(AND(F8="",I8=""),"No estimable con los datos disponibles.",IF(MAX(N(F8),N(I8))>=0.3,"Señal apreciable: vale la pena priorizar este río para el corredor.",IF(MAX(N(F8),N(I8))>=0.15,"Señal moderada.","Señal débil: la caña no explica la variabilidad observada."))) -> Señal apreciable: vale la pena priorizar este río para el corredor.
A9: Fraile | B9: 3 | C9: 4990 | D9: =B45 -> 16 | E9: =C45 -> -6.2688117e-05 | F9: =D45 -> 0.053012274 | G9: =B46 -> 43 | H9: =C46 -> 4.6469891e-05 | I9: =D46 -> 0.032685238 | J9: =IF(AND(F9="",I9=""),"No estimable con los datos disponibles.",IF(MAX(N(F9),N(I9))>=0.3,"Señal apreciable: vale la pena priorizar este río para el corredor.",IF(MAX(N(F9),N(I9))>=0.15,"Señal moderada.","Señal débil: la caña no explica la variabilidad observada."))) -> Señal débil: la caña no explica la variabilidad observada.
A10: Guachal | B10: 2 | C10: 654.7 | D10: =B56 -> 5 | E10: =C56 | F10: =D56 | G10: =B57 -> 16 | H10: =C57 | I10: =D57 | J10: =IF(AND(F10="",I10=""),"No estimable con los datos disponibles.",IF(MAX(N(F10),N(I10))>=0.3,"Señal apreciable: vale la pena priorizar este río para el corredor.",IF(MAX(N(F10),N(I10))>=0.15,"Señal moderada.","Señal débil: la caña no explica la variabilidad observada."))) -> No estimable con los datos disponibles.
A11: Palo | B11: 8 | C11: 511.1 | D11: =B73 -> 63 | E11: =C73 -> 0.00015245638 | F11: =D73 -> 0.10105582 | G11: =B74 -> 70 | H11: =C74 -> 0.0014164488 | I11: =D74 -> 0.028462713 | J11: =IF(AND(F11="",I11=""),"No estimable con los datos disponibles.",IF(MAX(N(F11),N(I11))>=0.3,"Señal apreciable: vale la pena priorizar este río para el corredor.",IF(MAX(N(F11),N(I11))>=0.15,"Señal moderada.","Señal débil: la caña no explica la variabilidad observada."))) -> Señal débil: la caña no explica la variabilidad observada.
A12: Desbaratado | B12: 2 | C12: 1613.7 | D12: =B84 -> 18 | E12: =C84 -> 3.3039781e-05 | F12: =D84 -> 0.086381362 | G12: =B85 -> 22 | H12: =C85 -> 0.00019932433 | I12: =D85 -> 0.039737629 | J12: =IF(AND(F12="",I12=""),"No estimable con los datos disponibles.",IF(MAX(N(F12),N(I12))>=0.3,"Señal apreciable: vale la pena priorizar este río para el corredor.",IF(MAX(N(F12),N(I12))>=0.15,"Señal moderada.","Señal débil: la caña no explica la variabilidad observada."))) -> Señal débil: la caña no explica la variabilidad observada.
A13: Amaime | B13: 3 | C13: 3475.9 | D13: =B96 -> 22 | E13: =C96 -> 2.0177269e-05 | F13: =D96 -> 0.014155689 | G13: =B97 -> 57 | H13: =C97 -> 5.143911e-06 | I13: =D97 -> 0.0001778153 | J13: =IF(AND(F13="",I13=""),"No estimable con los datos disponibles.",IF(MAX(N(F13),N(I13))>=0.3,"Señal apreciable: vale la pena priorizar este río para el corredor.",IF(MAX(N(F13),N(I13))>=0.15,"Señal moderada.","Señal débil: la caña no explica la variabilidad observada."))) -> Señal débil: la caña no explica la variabilidad observada.
A14: Nima | B14: 1 | C14: 896.6 | D14: =B106 -> 7 | E14: =C106 | F14: =D106 | G14: =B107 -> 18 | H14: =C107 | I14: =D107 | J14: =IF(AND(F14="",I14=""),"No estimable con los datos disponibles.",IF(MAX(N(F14),N(I14))>=0.3,"Señal apreciable: vale la pena priorizar este río para el corredor.",IF(MAX(N(F14),N(I14))>=0.15,"Señal moderada.","Señal débil: la caña no explica la variabilidad observada."))) -> No estimable con los datos disponibles.
A15: Guabas | B15: 1 | C15: 1825.8 | D15: =B116 -> 7 | E15: =C116 | F15: =D116 | G15: =B117 -> 17 | H15: =C117 | I15: =D117 | J15: =IF(AND(F15="",I15=""),"No estimable con los datos disponibles.",IF(MAX(N(F15),N(I15))>=0.3,"Señal apreciable: vale la pena priorizar este río para el corredor.",IF(MAX(N(F15),N(I15))>=0.15,"Señal moderada.","Señal débil: la caña no explica la variabilidad observada."))) -> No estimable con los datos disponibles.
A16: Zabaletas | B16: 3 | C16: 2527 | D16: =B128 -> 24 | E16: =C128 -> 0.00011947183 | F16: =D128 -> 0.47706049 | G16: =B129 -> 48 | H16: =C129 -> 0.00010137284 | I16: =D129 -> 0.32303598 | J16: =IF(AND(F16="",I16=""),"No estimable con los datos disponibles.",IF(MAX(N(F16),N(I16))>=0.3,"Señal apreciable: vale la pena priorizar este río para el corredor.",IF(MAX(N(F16),N(I16))>=0.15,"Señal moderada.","Señal débil: la caña no explica la variabilidad observada."))) -> Señal apreciable: vale la pena priorizar este río para el corredor.
A17: Guadalajara | B17: 3 | C17: 266.9 | D17: =B140 -> 18 | E17: =C140 -> 0.0014339016 | F17: =D140 -> 0.23143805 | G17: =B141 -> 57 | H17: =C141 -> 2.6637876e-05 | I17: =D141 -> 1.9702656e-05 | J17: =IF(AND(F17="",I17=""),"No estimable con los datos disponibles.",IF(MAX(N(F17),N(I17))>=0.3,"Señal apreciable: vale la pena priorizar este río para el corredor.",IF(MAX(N(F17),N(I17))>=0.15,"Señal moderada.","Señal débil: la caña no explica la variabilidad observada."))) -> Señal moderada.
A18: Riofrío | B18: 4 | C18: 504.8 | D18: =B153 -> 21 | E18: =C153 -> 7.7849142e-05 | F18: =D153 -> 0.016196064 | G18: =B154 -> 70 | H18: =C154 -> -2.3198857e-05 | I18: =D154 -> 0.0046520533 | J18: =IF(AND(F18="",I18=""),"No estimable con los datos disponibles.",IF(MAX(N(F18),N(I18))>=0.3,"Señal apreciable: vale la pena priorizar este río para el corredor.",IF(MAX(N(F18),N(I18))>=0.15,"Señal moderada.","Señal débil: la caña no explica la variabilidad observada."))) -> Señal débil: la caña no explica la variabilidad observada.
A19: Tuluá | B19: 4 | C19: 631.3 | D19: =B166 -> 32 | E19: =C166 -> 0.0013701949 | F19: =D166 -> 0.32636082 | G19: =B167 -> 70 | H19: =C167 -> 0.0018872676 | I19: =D167 -> 0.23102077 | J19: =IF(AND(F19="",I19=""),"No estimable con los datos disponibles.",IF(MAX(N(F19),N(I19))>=0.3,"Señal apreciable: vale la pena priorizar este río para el corredor.",IF(MAX(N(F19),N(I19))>=0.15,"Señal moderada.","Señal débil: la caña no explica la variabilidad observada."))) -> Señal apreciable: vale la pena priorizar este río para el corredor.
A20: Bugalagrande | B20: 3 | C20: 1282.6 | D20: =B178 -> 21 | E20: =C178 -> 8.0324928e-05 | F20: =D178 -> 0.010120564 | G20: =B179 -> 54 | H20: =C179 -> 3.9024796e-05 | I20: =D179 -> 0.058944076 | J20: =IF(AND(F20="",I20=""),"No estimable con los datos disponibles.",IF(MAX(N(F20),N(I20))>=0.3,"Señal apreciable: vale la pena priorizar este río para el corredor.",IF(MAX(N(F20),N(I20))>=0.15,"Señal moderada.","Señal débil: la caña no explica la variabilidad observada."))) -> Señal débil: la caña no explica la variabilidad observada.
A21: La Paila | B21: 3 | C21: 1438.9 | D21: =B190 -> 18 | E21: =C190 -> 0.00011061465 | F21: =D190 -> 0.18638091 | G21: =B191 -> 54 | H21: =C191 -> 0.00045489998 | I21: =D191 -> 0.14444054 | J21: =IF(AND(F21="",I21=""),"No estimable con los datos disponibles.",IF(MAX(N(F21),N(I21))>=0.3,"Señal apreciable: vale la pena priorizar este río para el corredor.",IF(MAX(N(F21),N(I21))>=0.15,"Señal moderada.","Señal débil: la caña no explica la variabilidad observada."))) -> Señal moderada.
A22: Risaralda | B22: 3 | C22: 678.4 | D22: =B202 -> 1 | E22: =C202 | F22: =D202 | G22: =B203 -> 1 | H22: =C203 | I22: =D203 | J22: =IF(AND(F22="",I22=""),"No estimable con los datos disponibles.",IF(MAX(N(F22),N(I22))>=0.3,"Señal apreciable: vale la pena priorizar este río para el corredor.",IF(MAX(N(F22),N(I22))>=0.15,"Señal moderada.","Señal débil: la caña no explica la variabilidad observada."))) -> No estimable con los datos disponibles.
A25: RÍO BOLO — 3 tramos · 3.794,8 ha de caña en el buffer de 700 m
A26: Tramo (abscisa · estación de entrada → estación de cierre) | B26: Long. (km) | C26: Área caña tramo (ha) | D26: Área caña acum. (ha) | E26: Carga N acum. mín (kg/año) | F26: Carga N acum. prom (kg/año) | G26: Carga N acum. máx (kg/año) | H26: Carga P acum. mín | I26: Carga P acum. prom | J26: Carga P acum. máx | L26: n N | M26: N-Total prom (mg/L) | N26: N-Total desv. est. | O26: n P | P26: P-Total prom (mg/L) | Q26: P-Total desv. est.
A27: Tramo 1 (0,00–10,94 km) Limnígrafo CVC - Los Minchos → Puente Pradera - Palmira | B27: 10.938 | C27: 292.41 | D27: 292.41 | E27: =$D27*Parametros!$B$22 -> 877.23 | F27: =$D27*Parametros!$C$22 -> 1403.568 | G27: =$D27*Parametros!$D$22 -> 2924.1 | H27: =$D27*Parametros!$B$23 -> 29.241 | I27: =$D27*Parametros!$C$23 -> 175.446 | J27: =$D27*Parametros!$D$23 -> 438.615 | L27: =COUNTIFS(Datos_Individuales!$C$5:$C$52,"Rio Bolo - Puente Pradera - Palmira",Datos_Individuales!$G$5:$G$52,"<>") -> 6 | M27: =IF($L27=0,"",AVERAGEIFS(Datos_Individuales!$G$5:$G$52,Datos_Individuales!$C$5:$C$52,"Rio Bolo - Puente Pradera - Palmira")) -> 1.1098333 | N27: =IF($L27<2,"",SQRT(SUMPRODUCT((Datos_Individuales!$C$5:$C$52="Rio Bolo - Puente Pradera - Palmira")*(Datos_Individuales!$G$5:$G$52<>"")*(Datos_Individuales!$G$5:$G$52-$M27)^2)/($L27-1))) -> 0.74259341 | O27: =COUNTIFS(Datos_Individuales!$C$5:$C$52,"Rio Bolo - Puente Pradera - Palmira",Datos_Individuales!$I$5:$I$52,"<>") -> 16 | P27: =IF($O27=0,"",AVERAGEIFS(Datos_Individuales!$I$5:$I$52,Datos_Individuales!$C$5:$C$52,"Rio Bolo - Puente Pradera - Palmira")) -> 0.1079625 | Q27: =IF($O27<2,"",SQRT(SUMPRODUCT((Datos_Individuales!$C$5:$C$52="Rio Bolo - Puente Pradera - Palmira")*(Datos_Individuales!$I$5:$I$52<>"")*(Datos_Individuales!$I$5:$I$52-$P27)^2)/($O27-1))) -> 0.029680968
A28: Tramo 2 (10,94–30,02 km) Puente Pradera - Palmira → Puente Bolo - San Isidro - vía a Candelaria | B28: 19.085 | C28: 1610.19 | D28: 1902.6 | E28: =$D28*Parametros!$B$22 -> 5707.8 | F28: =$D28*Parametros!$C$22 -> 9132.48 | G28: =$D28*Parametros!$D$22 -> 19026 | H28: =$D28*Parametros!$B$23 -> 190.26 | I28: =$D28*Parametros!$C$23 -> 1141.56 | J28: =$D28*Parametros!$D$23 -> 2853.9 | L28: =COUNTIFS(Datos_Individuales!$C$5:$C$52,"Rio Bolo - Puente Bolo - San Isidro - vía a Candelaria",Datos_Individuales!$G$5:$G$52,"<>") -> 6 | M28: =IF($L28=0,"",AVERAGEIFS(Datos_Individuales!$G$5:$G$52,Datos_Individuales!$C$5:$C$52,"Rio Bolo - Puente Bolo - San Isidro - vía a Candelaria")) -> 3.0891667 | N28: =IF($L28<2,"",SQRT(SUMPRODUCT((Datos_Individuales!$C$5:$C$52="Rio Bolo - Puente Bolo - San Isidro - vía a Candelaria")*(Datos_Individuales!$G$5:$G$52<>"")*(Datos_Individuales!$G$5:$G$52-$M28)^2)/($L28-1))) -> 2.5449173 | O28: =COUNTIFS(Datos_Individuales!$C$5:$C$52,"Rio Bolo - Puente Bolo - San Isidro - vía a Candelaria",Datos_Individuales!$I$5:$I$52,"<>") -> 16 | P28: =IF($O28=0,"",AVERAGEIFS(Datos_Individuales!$I$5:$I$52,Datos_Individuales!$C$5:$C$52,"Rio Bolo - Puente Bolo - San Isidro - vía a Candelaria")) -> 0.1478125 | Q28: =IF($O28<2,"",SQRT(SUMPRODUCT((Datos_Individuales!$C$5:$C$52="Rio Bolo - Puente Bolo - San Isidro - vía a Candelaria")*(Datos_Individuales!$I$5:$I$52<>"")*(Datos_Individuales!$I$5:$I$52-$P28)^2)/($O28-1))) -> 0.08805583
A29: Tramo 3 (30,02–48,01 km) Puente Bolo - San Isidro - vía a Candelaria → Antes desembocadura a Frayle en puente Recta Cali - Palmira | B29: 17.982 | C29: 1892.25 | D29: 3794.85 | E29: =$D29*Parametros!$B$22 -> 11384.55 | F29: =$D29*Parametros!$C$22 -> 18215.28 | G29: =$D29*Parametros!$D$22 -> 37948.5 | H29: =$D29*Parametros!$B$23 -> 379.485 | I29: =$D29*Parametros!$C$23 -> 2276.91 | J29: =$D29*Parametros!$D$23 -> 5692.275 | L29: =COUNTIFS(Datos_Individuales!$C$5:$C$52,"Rio Bolo - Antes desembocadura a Frayle en puente Recta Cali - Palmira",Datos_Individuales!$G$5:$G$52,"<>") -> 6 | M29: =IF($L29=0,"",AVERAGEIFS(Datos_Individuales!$G$5:$G$52,Datos_Individuales!$C$5:$C$52,"Rio Bolo - Antes desembocadura a Frayle en puente Recta Cali - Palmira")) -> 3.014 | N29: =IF($L29<2,"",SQRT(SUMPRODUCT((Datos_Individuales!$C$5:$C$52="Rio Bolo - Antes desembocadura a Frayle en puente Recta Cali - Palmira")*(Datos_Individuales!$G$5:$G$52<>"")*(Datos_Individuales!$G$5:$G$52-$M29)^2)/($L29-1))) -> 1.8087432 | O29: =COUNTIFS(Datos_Individuales!$C$5:$C$52,"Rio Bolo - Antes desembocadura a Frayle en puente Recta Cali - Palmira",Datos_Individuales!$I$5:$I$52,"<>") -> 16 | P29: =IF($O29=0,"",AVERAGEIFS(Datos_Individuales!$I$5:$I$52,Datos_Individuales!$C$5:$C$52,"Rio Bolo - Antes desembocadura a Frayle en puente Recta Cali - Palmira")) -> 0.285775 | Q29: =IF($O29<2,"",SQRT(SUMPRODUCT((Datos_Individuales!$C$5:$C$52="Rio Bolo - Antes desembocadura a Frayle en puente Recta Cali - Palmira")*(Datos_Individuales!$I$5:$I$52<>"")*(Datos_Individuales!$I$5:$I$52-$P29)^2)/($O29-1))) -> 0.16958285
A30: Total del río | B30: =SUM(B27:B29) -> 48.005 | C30: =SUM(C27:C29) -> 3794.85 | D30: =D29 -> 3794.85 | E30: =E29 -> 11384.55 | F30: =F29 -> 18215.28 | G30: =G29 -> 37948.5 | H30: =H29 -> 379.485 | I30: =I29 -> 2276.91 | J30: =J29 -> 5692.275
A31: REGRESIÓN SOBRE MEDICIONES INDIVIDUALES — x = carga de caña acumulada aguas arriba (kg/año, escenario promedio) · y = cada medición puntual de la estación
A32: Parámetro | B32: n datos | C32: Pendiente (mg/L)/(kg/año) | D32: R² | E32: Correlación r | F32: Interpretación
A33: Nitrógeno Total | B33: =COUNT(Datos_Individuales!$G$5:$G$52) -> 18 | C33: =IF($B33<3,"",IFERROR(SLOPE(Datos_Individuales!$G$5:$G$52,Datos_Individuales!$F$5:$F$52),"")) -> 0.00010974651 | D33: =IF($B33<3,"",IFERROR(RSQ(Datos_Individuales!$G$5:$G$52,Datos_Individuales!$F$5:$F$52),"")) -> 0.15367841 | E33: =IF($B33<3,"",IFERROR(CORREL(Datos_Individuales!$G$5:$G$52,Datos_Individuales!$F$5:$F$52),"")) -> 0.39201838 | F33: =IF($B33<3,"Datos insuficientes para regresar.",IF($D33="","Todas las mediciones provienen de una sola estación: el eje x no varía y la regresión no es estimable.",IF($C33<0,"Pendiente negativa: la concentración baja al aumentar la caña aguas arriba. No hay señal atribuible a la caña.",IF($D33<0.1,"La carga de caña explica menos del 10% de la variabilidad observada.",IF($D33<0.3,"Asociación débil: la caña explica una fracción menor de la variabilidad.",IF($D33<0.5,"Asociación moderada.","Asociación relativamente fuerte para dato observacional.")))))) -> Asociación débil: la caña explica una fracción menor de la variabilidad.
A34: Fósforo Total | B34: =COUNT(Datos_Individuales!$I$5:$I$52) -> 48 | C34: =IF($B34<3,"",IFERROR(SLOPE(Datos_Individuales!$I$5:$I$52,Datos_Individuales!$H$5:$H$52),"")) -> 8.5681694e-05 | D34: =IF($B34<3,"",IFERROR(RSQ(Datos_Individuales!$I$5:$I$52,Datos_Individuales!$H$5:$H$52),"")) -> 0.3096169 | E34: =IF($B34<3,"",IFERROR(CORREL(Datos_Individuales!$I$5:$I$52,Datos_Individuales!$H$5:$H$52),"")) -> 0.5564323 | F34: =IF($B34<3,"Datos insuficientes para regresar.",IF($D34="","Todas las mediciones provienen de una sola estación: el eje x no varía y la regresión no es estimable.",IF($C34<0,"Pendiente negativa: la concentración baja al aumentar la caña aguas arriba. No hay señal atribuible a la caña.",IF($D34<0.1,"La carga de caña explica menos del 10% de la variabilidad observada.",IF($D34<0.3,"Asociación débil: la caña explica una fracción menor de la variabilidad.",IF($D34<0.5,"Asociación moderada.","Asociación relativamente fuerte para dato observacional.")))))) -> Asociación moderada.
A37: RÍO FRAILE — 3 tramos · 4.990,0 ha de caña en el buffer de 700 m
A38: Tramo (abscisa · estación de entrada → estación de cierre) | B38: Long. (km) | C38: Área caña tramo (ha) | D38: Área caña acum. (ha) | E38: Carga N acum. mín (kg/año) | F38: Carga N acum. prom (kg/año) | G38: Carga N acum. máx (kg/año) | H38: Carga P acum. mín | I38: Carga P acum. prom | J38: Carga P acum. máx | L38: n N | M38: N-Total prom (mg/L) | N38: N-Total desv. est. | O38: n P | P38: P-Total prom (mg/L) | Q38: P-Total desv. est.
A39: Tramo 1 (0,00–28,88 km) Nacimiento El Pedregal → Puente Vía a Miranda | B39: 28.879 | C39: 92.77 | D39: 92.77 | E39: =$D39*Parametros!$B$22 -> 278.31 | F39: =$D39*Parametros!$C$22 -> 445.296 | G39: =$D39*Parametros!$D$22 -> 927.7 | H39: =$D39*Parametros!$B$23 -> 9.277 | I39: =$D39*Parametros!$C$23 -> 55.662 | J39: =$D39*Parametros!$D$23 -> 139.155 | L39: =COUNTIFS(Datos_Individuales!$C$53:$C$95,"Rio Frayle - Puente Vía a Miranda",Datos_Individuales!$G$53:$G$95,"<>") -> 6 | M39: =IF($L39=0,"",AVERAGEIFS(Datos_Individuales!$G$53:$G$95,Datos_Individuales!$C$53:$C$95,"Rio Frayle - Puente Vía a Miranda")) -> 4.3888333 | N39: =IF($L39<2,"",SQRT(SUMPRODUCT((Datos_Individuales!$C$53:$C$95="Rio Frayle - Puente Vía a Miranda")*(Datos_Individuales!$G$53:$G$95<>"")*(Datos_Individuales!$G$53:$G$95-$M39)^2)/($L39-1))) -> 3.8163176 | O39: =COUNTIFS(Datos_Individuales!$C$53:$C$95,"Rio Frayle - Puente Vía a Miranda",Datos_Individuales!$I$53:$I$95,"<>") -> 16 | P39: =IF($O39=0,"",AVERAGEIFS(Datos_Individuales!$I$53:$I$95,Datos_Individuales!$C$53:$C$95,"Rio Frayle - Puente Vía a Miranda")) -> 0.28624375 | Q39: =IF($O39<2,"",SQRT(SUMPRODUCT((Datos_Individuales!$C$53:$C$95="Rio Frayle - Puente Vía a Miranda")*(Datos_Individuales!$I$53:$I$95<>"")*(Datos_Individuales!$I$53:$I$95-$P39)^2)/($O39-1))) -> 0.36581053
A40: Tramo 2 (28,88–52,14 km) Puente Vía a Miranda → Limnigrafo CVC - caserio Brisas de Frayle | B40: 23.263 | C40: 1948.71 | D40: 2041.48 | E40: =$D40*Parametros!$B$22 -> 6124.44 | F40: =$D40*Parametros!$C$22 -> 9799.104 | G40: =$D40*Parametros!$D$22 -> 20414.8 | H40: =$D40*Parametros!$B$23 -> 204.148 | I40: =$D40*Parametros!$C$23 -> 1224.888 | J40: =$D40*Parametros!$D$23 -> 3062.22 | L40: =COUNTIFS(Datos_Individuales!$C$53:$C$95,"Rio Frayle - Limnigrafo CVC - caserio Brisas de Frayle",Datos_Individuales!$G$53:$G$95,"<>") -> 6 | M40: =IF($L40=0,"",AVERAGEIFS(Datos_Individuales!$G$53:$G$95,Datos_Individuales!$C$53:$C$95,"Rio Frayle - Limnigrafo CVC - caserio Brisas de Frayle")) -> 2.1866667 | N40: =IF($L40<2,"",SQRT(SUMPRODUCT((Datos_Individuales!$C$53:$C$95="Rio Frayle - Limnigrafo CVC - caserio Brisas de Frayle")*(Datos_Individuales!$G$53:$G$95<>"")*(Datos_Individuales!$G$53:$G$95-$M40)^2)/($L40-1))) -> 1.2481293 | O40: =COUNTIFS(Datos_Individuales!$C$53:$C$95,"Rio Frayle - Limnigrafo CVC - caserio Brisas de Frayle",Datos_Individuales!$I$53:$I$95,"<>") -> 16 | P40: =IF($O40=0,"",AVERAGEIFS(Datos_Individuales!$I$53:$I$95,Datos_Individuales!$C$53:$C$95,"Rio Frayle - Limnigrafo CVC - caserio Brisas de Frayle")) -> 0.2225625 | Q40: =IF($O40<2,"",SQRT(SUMPRODUCT((Datos_Individuales!$C$53:$C$95="Rio Frayle - Limnigrafo CVC - caserio Brisas de Frayle")*(Datos_Individuales!$I$53:$I$95<>"")*(Datos_Individuales!$I$53:$I$95-$P40)^2)/($O40-1))) -> 0.21983462
A41: Tramo 3 (52,14–80,62 km) Limnigrafo CVC - caserio Brisas de Frayle → Antes Desembocadura a rio Guachal Recta Cali Palmira | B41: 28.479 | C41: 2948.52 | D41: 4990 | E41: =$D41*Parametros!$B$22 -> 14970 | F41: =$D41*Parametros!$C$22 -> 23952 | G41: =$D41*Parametros!$D$22 -> 49900 | H41: =$D41*Parametros!$B$23 -> 499 | I41: =$D41*Parametros!$C$23 -> 2994 | J41: =$D41*Parametros!$D$23 -> 7485 | L41: =COUNTIFS(Datos_Individuales!$C$53:$C$95,"Rio Frayle - Antes Desembocadura a rio Guachal Recta Cali Palmira",Datos_Individuales!$G$53:$G$95,"<>") -> 4 | M41: =IF($L41=0,"",AVERAGEIFS(Datos_Individuales!$G$53:$G$95,Datos_Individuales!$C$53:$C$95,"Rio Frayle - Antes Desembocadura a rio Guachal Recta Cali Palmira")) -> 2.91 | N41: =IF($L41<2,"",SQRT(SUMPRODUCT((Datos_Individuales!$C$53:$C$95="Rio Frayle - Antes Desembocadura a rio Guachal Recta Cali Palmira")*(Datos_Individuales!$G$53:$G$95<>"")*(Datos_Individuales!$G$53:$G$95-$M41)^2)/($L41-1))) -> 0.95243547 | O41: =COUNTIFS(Datos_Individuales!$C$53:$C$95,"Rio Frayle - Antes Desembocadura a rio Guachal Recta Cali Palmira",Datos_Individuales!$I$53:$I$95,"<>") -> 11 | P41: =IF($O41=0,"",AVERAGEIFS(Datos_Individuales!$I$53:$I$95,Datos_Individuales!$C$53:$C$95,"Rio Frayle - Antes Desembocadura a rio Guachal Recta Cali Palmira")) -> 0.42107273 | Q41: =IF($O41<2,"",SQRT(SUMPRODUCT((Datos_Individuales!$C$53:$C$95="Rio Frayle - Antes Desembocadura a rio Guachal Recta Cali Palmira")*(Datos_Individuales!$I$53:$I$95<>"")*(Datos_Individuales!$I$53:$I$95-$P41)^2)/($O41-1))) -> 0.26959283
A42: Total del río | B42: =SUM(B39:B41) -> 80.621 | C42: =SUM(C39:C41) -> 4990 | D42: =D41 -> 4990 | E42: =E41 -> 14970 | F42: =F41 -> 23952 | G42: =G41 -> 49900 | H42: =H41 -> 499 | I42: =I41 -> 2994 | J42: =J41 -> 7485
A43: REGRESIÓN SOBRE MEDICIONES INDIVIDUALES — x = carga de caña acumulada aguas arriba (kg/año, escenario promedio) · y = cada medición puntual de la estación
A44: Parámetro | B44: n datos | C44: Pendiente (mg/L)/(kg/año) | D44: R² | E44: Correlación r | F44: Interpretación
A45: Nitrógeno Total | B45: =COUNT(Datos_Individuales!$G$53:$G$95) -> 16 | C45: =IF($B45<3,"",IFERROR(SLOPE(Datos_Individuales!$G$53:$G$95,Datos_Individuales!$F$53:$F$95),"")) -> -6.2688117e-05 | D45: =IF($B45<3,"",IFERROR(RSQ(Datos_Individuales!$G$53:$G$95,Datos_Individuales!$F$53:$F$95),"")) -> 0.053012274 | E45: =IF($B45<3,"",IFERROR(CORREL(Datos_Individuales!$G$53:$G$95,Datos_Individuales!$F$53:$F$95),"")) -> -0.23024395 | F45: =IF($B45<3,"Datos insuficientes para regresar.",IF($D45="","Todas las mediciones provienen de una sola estación: el eje x no varía y la regresión no es estimable.",IF($C45<0,"Pendiente negativa: la concentración baja al aumentar la caña aguas arriba. No hay señal atribuible a la caña.",IF($D45<0.1,"La carga de caña explica menos del 10% de la variabilidad observada.",IF($D45<0.3,"Asociación débil: la caña explica una fracción menor de la variabilidad.",IF($D45<0.5,"Asociación moderada.","Asociación relativamente fuerte para dato observacional.")))))) -> Pendiente negativa: la concentración baja al aumentar la caña aguas arriba. No hay señal atribuible a la caña.
A46: Fósforo Total | B46: =COUNT(Datos_Individuales!$I$53:$I$95) -> 43 | C46: =IF($B46<3,"",IFERROR(SLOPE(Datos_Individuales!$I$53:$I$95,Datos_Individuales!$H$53:$H$95),"")) -> 4.6469891e-05 | D46: =IF($B46<3,"",IFERROR(RSQ(Datos_Individuales!$I$53:$I$95,Datos_Individuales!$H$53:$H$95),"")) -> 0.032685238 | E46: =IF($B46<3,"",IFERROR(CORREL(Datos_Individuales!$I$53:$I$95,Datos_Individuales!$H$53:$H$95),"")) -> 0.18079059 | F46: =IF($B46<3,"Datos insuficientes para regresar.",IF($D46="","Todas las mediciones provienen de una sola estación: el eje x no varía y la regresión no es estimable.",IF($C46<0,"Pendiente negativa: la concentración baja al aumentar la caña aguas arriba. No hay señal atribuible a la caña.",IF($D46<0.1,"La carga de caña explica menos del 10% de la variabilidad observada.",IF($D46<0.3,"Asociación débil: la caña explica una fracción menor de la variabilidad.",IF($D46<0.5,"Asociación moderada.","Asociación relativamente fuerte para dato observacional.")))))) -> La carga de caña explica menos del 10% de la variabilidad observada.
...

Sheet Datos_Individuales
A1: Mediciones individuales de calidad usadas en la regresión
A2: Cada fila es una muestra puntual de la red de monitoreo (fuente: Calidad_agua_completo_v12.xlsx, hoja CONSOLIDADO, columnas AF = Nitrógeno Total y AK = Fósforo Total). Solo se incluyen las estaciones que cierran un tramo en el archivo tramos_cana_tributarios.csv. El área de caña acumulada es la suma de las áreas de todos los tramos del río situados aguas arriba de la estación, inclusive. Los valores reportados por el laboratorio como "< LC" se contabilizaron con el límite de cuantificación completo.
A4: Río | B4: Tramo | C4: Estación | D4: Fecha | E4: Área caña acum. (ha) | F4: Carga N caña acum. (kg/año) | G4: N-Total (mg/L) | H4: Carga P caña acum. (kg/año) | I4: P-Total (mg/L)
A5: Bolo | B5: 1 | C5: Rio Bolo - Puente Pradera - Palmira | D5: 02/04/2019 | E5: 292.41 | F5: =$E5*Parametros!$C$22 -> 1403.568 | H5: =$E5*Parametros!$C$23 -> 175.446 | I5: 0.096
A6: Bolo | B6: 1 | C6: Rio Bolo - Puente Pradera - Palmira | D6: 03/05/2023 | E6: 292.41 | F6: =$E6*Parametros!$C$22 -> 1403.568 | G6: 0.745 | H6: =$E6*Parametros!$C$23 -> 175.446 | I6: 0.0946
A7: Bolo | B7: 1 | C7: Rio Bolo - Puente Pradera - Palmira | D7: 07/10/2024 | E7: 292.41 | F7: =$E7*Parametros!$C$22 -> 1403.568 | G7: 0.828 | H7: =$E7*Parametros!$C$23 -> 175.446 | I7: 0.13
A8: Bolo | B8: 1 | C8: Rio Bolo - Puente Pradera - Palmira | D8: 09/08/2021 | E8: 292.41 | F8: =$E8*Parametros!$C$22 -> 1403.568 | H8: =$E8*Parametros!$C$23 -> 175.446 | I8: 0.142
A9: Bolo | B9: 1 | C9: Rio Bolo - Puente Pradera - Palmira | D9: 12/05/2022 | E9: 292.41 | F9: =$E9*Parametros!$C$22 -> 1403.568 | G9: 0.5 | H9: =$E9*Parametros!$C$23 -> 175.446 | I9: 0.0959
A10: Bolo | B10: 1 | C10: Rio Bolo - Puente Pradera - Palmira | D10: 12/09/2023 | E10: 292.41 | F10: =$E10*Parametros!$C$22 -> 1403.568 | H10: =$E10*Parametros!$C$23 -> 175.446 | I10: 0.101
A11: Bolo | B11: 1 | C11: Rio Bolo - Puente Pradera - Palmira | D11: 14/06/2016 | E11: 292.41 | F11: =$E11*Parametros!$C$22 -> 1403.568 | H11: =$E11*Parametros!$C$23 -> 175.446 | I11: 0.186
A12: Bolo | B12: 1 | C12: Rio Bolo - Puente Pradera - Palmira | D12: 16/04/2018 | E12: 292.41 | F12: =$E12*Parametros!$C$22 -> 1403.568 | H12: =$E12*Parametros!$C$23 -> 175.446 | I12: 0.091
A13: Bolo | B13: 1 | C13: Rio Bolo - Puente Pradera - Palmira | D13: 21/08/2019 | E13: 292.41 | F13: =$E13*Parametros!$C$22 -> 1403.568 | H13: =$E13*Parametros!$C$23 -> 175.446 | I13: 0.0662
A14: Bolo | B14: 1 | C14: Rio Bolo - Puente Pradera - Palmira | D14: 22/04/2024 | E14: 292.41 | F14: =$E14*Parametros!$C$22 -> 1403.568 | H14: =$E14*Parametros!$C$23 -> 175.446 | I14: 0.1
A15: Bolo | B15: 1 | C15: Rio Bolo - Puente Pradera - Palmira | D15: 22/05/2025 | E15: 292.41 | F15: =$E15*Parametros!$C$22 -> 1403.568 | G15: 1.5 | H15: =$E15*Parametros!$C$23 -> 175.446 | I15: 0.0946
A16: Bolo | B16: 1 | C16: Rio Bolo - Puente Pradera - Palmira | D16: 22/08/2017 | E16: 292.41 | F16: =$E16*Parametros!$C$22 -> 1403.568 | H16: =$E16*Parametros!$C$23 -> 175.446 | I16: 0.0662
A17: Bolo | B17: 1 | C17: Rio Bolo - Puente Pradera - Palmira | D17: 23/08/2022 | E17: 292.41 | F17: =$E17*Parametros!$C$22 -> 1403.568 | G17: 0.636 | H17: =$E17*Parametros!$C$23 -> 175.446 | I17: 0.0959
A18: Bolo | B18: 1 | C18: Rio Bolo - Puente Pradera - Palmira | D18: 24/11/2021 | E18: 292.41 | F18: =$E18*Parametros!$C$22 -> 1403.568 | H18: =$E18*Parametros!$C$23 -> 175.446 | I18: 0.125
A19: Bolo | B19: 1 | C19: Rio Bolo - Puente Pradera - Palmira | D19: 26/04/2017 | E19: 292.41 | F19: =$E19*Parametros!$C$22 -> 1403.568 | G19: 2.45 | H19: =$E19*Parametros!$C$23 -> 175.446 | I19: 0.113
A20: Bolo | B20: 1 | C20: Rio Bolo - Puente Pradera - Palmira | D20: 31/10/2016 | E20: 292.41 | F20: =$E20*Parametros!$C$22 -> 1403.568 | H20: =$E20*Parametros!$C$23 -> 175.446 | I20: 0.13
A21: Bolo | B21: 2 | C21: Rio Bolo - Puente Bolo - San Isidro - vía a Candelaria | D21: 02/04/2019 | E21: 1902.6 | F21: =$E21*Parametros!$C$22 -> 9132.48 | H21: =$E21*Parametros!$C$23 -> 1141.56 | I21: 0.379
A22: Bolo | B22: 2 | C22: Rio Bolo - Puente Bolo - San Isidro - vía a Candelaria | D22: 03/05/2023 | E22: 1902.6 | F22: =$E22*Parametros!$C$22 -> 9132.48 | G22: 1.27 | H22: =$E22*Parametros!$C$23 -> 1141.56 | I22: 0.1
A23: Bolo | B23: 2 | C23: Rio Bolo - Puente Bolo - San Isidro - vía a Candelaria | D23: 07/10/2024 | E23: 1902.6 | F23: =$E23*Parametros!$C$22 -> 9132.48 | G23: 5.98 | H23: =$E23*Parametros!$C$23 -> 1141.56 | I23: 0.0946
A24: Bolo | B24: 2 | C24: Rio Bolo - Puente Bolo - San Isidro - vía a Candelaria | D24: 09/08/2021 | E24: 1902.6 | F24: =$E24*Parametros!$C$22 -> 9132.48 | H24: =$E24*Parametros!$C$23 -> 1141.56 | I24: 0.0959
A25: Bolo | B25: 2 | C25: Rio Bolo - Puente Bolo - San Isidro - vía a Candelaria | D25: 12/05/2022 | E25: 1902.6 | F25: =$E25*Parametros!$C$22 -> 9132.48 | G25: 1.28 | H25: =$E25*Parametros!$C$23 -> 1141.56 | I25: 0.0959
A26: Bolo | B26: 2 | C26: Rio Bolo - Puente Bolo - San Isidro - vía a Candelaria | D26: 12/09/2023 | E26: 1902.6 | F26: =$E26*Parametros!$C$22 -> 9132.48 | H26: =$E26*Parametros!$C$23 -> 1141.56 | I26: 0.0946
A27: Bolo | B27: 2 | C27: Rio Bolo - Puente Bolo - San Isidro - vía a Candelaria | D27: 14/06/2016 | E27: 1902.6 | F27: =$E27*Parametros!$C$22 -> 9132.48 | H27: =$E27*Parametros!$C$23 -> 1141.56 | I27: 0.265
A28: Bolo | B28: 2 | C28: Rio Bolo - Puente Bolo - San Isidro - vía a Candelaria | D28: 16/04/2018 | E28: 1902.6 | F28: =$E28*Parametros!$C$22 -> 9132.48 | H28: =$E28*Parametros!$C$23 -> 1141.56 | I28: 0.087
A29: Bolo | B29: 2 | C29: Rio Bolo - Puente Bolo - San Isidro - vía a Candelaria | D29: 21/08/2019 | E29: 1902.6 | F29: =$E29*Parametros!$C$22 -> 9132.48 | H29: =$E29*Parametros!$C$23 -> 1141.56 | I29: 0.0662
A30: Bolo | B30: 2 | C30: Rio Bolo - Puente Bolo - San Isidro - vía a Candelaria | D30: 22/04/2024 | E30: 1902.6 | F30: =$E30*Parametros!$C$22 -> 9132.48 | H30: =$E30*Parametros!$C$23 -> 1141.56 | I30: 0.176
A31: Bolo | B31: 2 | C31: Rio Bolo - Puente Bolo - San Isidro - vía a Candelaria | D31: 22/05/2025 | E31: 1902.6 | F31: =$E31*Parametros!$C$22 -> 9132.48 | G31: 2.5 | H31: =$E31*Parametros!$C$23 -> 1141.56 | I31: 0.14
A32: Bolo | B32: 2 | C32: Rio Bolo - Puente Bolo - San Isidro - vía a Candelaria | D32: 22/08/2017 | E32: 1902.6 | F32: =$E32*Parametros!$C$22 -> 9132.48 | H32: =$E32*Parametros!$C$23 -> 1141.56 | I32: 0.1
A33: Bolo | B33: 2 | C33: Rio Bolo - Puente Bolo - San Isidro - vía a Candelaria | D33: 23/08/2022 | E33: 1902.6 | F33: =$E33*Parametros!$C$22 -> 9132.48 | G33: 0.905 | H33: =$E33*Parametros!$C$23 -> 1141.56 | I33: 0.0959
A34: Bolo | B34: 2 | C34: Rio Bolo - Puente Bolo - San Isidro - vía a Candelaria | D34: 24/11/2021 | E34: 1902.6 | F34: =$E34*Parametros!$C$22 -> 9132.48 | H34: =$E34*Parametros!$C$23 -> 1141.56 | I34: 0.0959
A35: Bolo | B35: 2 | C35: Rio Bolo - Puente Bolo - San Isidro - vía a Candelaria | D35: 26/04/2017 | E35: 1902.6 | F35: =$E35*Parametros!$C$22 -> 9132.48 | G35: 6.6 | H35: =$E35*Parametros!$C$23 -> 1141.56 | I35: 0.246
A36: Bolo | B36: 2 | C36: Rio Bolo - Puente Bolo - San Isidro - vía a Candelaria | D36: 31/10/2016 | E36: 1902.6 | F36: =$E36*Parametros!$C$22 -> 9132.48 | H36: =$E36*Parametros!$C$23 -> 1141.56 | I36: 0.233
A37: Bolo | B37: 3 | C37: Rio Bolo - Antes desembocadura a Frayle en puente Recta Cali - Palmira | D37: 02/04/2019 | E37: 3794.85 | F37: =$E37*Parametros!$C$22 -> 18215.28 | H37: =$E37*Parametros!$C$23 -> 2276.91 | I37: 0.379
A38: Bolo | B38: 3 | C38: Rio Bolo - Antes desembocadura a Frayle en puente Recta Cali - Palmira | D38: 03/05/2023 | E38: 3794.85 | F38: =$E38*Parametros!$C$22 -> 18215.28 | G38: 1.95 | H38: =$E38*Parametros!$C$23 -> 2276.91 | I38: 0.43
A39: Bolo | B39: 3 | C39: Rio Bolo - Antes desembocadura a Frayle en puente Recta Cali - Palmira | D39: 07/10/2024 | E39: 3794.85 | F39: =$E39*Parametros!$C$22 -> 18215.28 | G39: 4.92 | H39: =$E39*Parametros!$C$23 -> 2276.91 | I39: 0.0946
A40: Bolo | B40: 3 | C40: Rio Bolo - Antes desembocadura a Frayle en puente Recta Cali - Palmira | D40: 09/08/2021 | E40: 3794.85 | F40: =$E40*Parametros!$C$22 -> 18215.28 | H40: =$E40*Parametros!$C$23 -> 2276.91 | I40: 0.177
A41: Bolo | B41: 3 | C41: Rio Bolo - Antes desembocadura a Frayle en puente Recta Cali - Palmira | D41: 12/05/2022 | E41: 3794.85 | F41: =$E41*Parametros!$C$22 -> 18215.28 | G41: 2.05 | H41: =$E41*Parametros!$C$23 -> 2276.91 | I41: 0.0959
...

Sheet Diagnostico_Caudal
A1: Por qué no fue posible normalizar por caudal
A2: La normalización por caudal (convertir la concentración observada en carga, kg/día = mg/L × L/s × 0,0864) permitiría comparar la carga estimada de la caña contra la carga realmente transportada por el río, eliminando el efecto de dilución. El archivo Calidad_agua_completo_v12.xlsx incluye una columna de caudal (CONSOLIDADO, columna AY), pero su contenido no permite hacer el cálculo. Esta hoja documenta el estado real del dato para poder solicitarlo formalmente a la CVC.
A4: Río | B4: Estación | C4: Muestras con caudal | D4: Caudal mín | E4: Caudal mediana | F4: Caudal máx
A5: Desbaratado | B5: Antes de bocatoma cabecera Miranda | C5: 17 | D5: 0 | E5: 2.94 | F5: 2126
A6: Desbaratado | B6: Antes de porcícola (Pte. Jordán) | C6: 17 | D6: 0 | E6: 2.824 | F6: 1469
A7: Desbaratado | B7: Puente Ortigal | C7: 15 | D7: 0 | E7: 3.051 | F7: 1520
A8: Palo | B8: Antes de PTAR Guachené | C8: 18 | D8: 0 | E8: 12.4385 | F8: 13122
A9: Palo | B9: Bocatoma corregimiento El Palo | C9: 4 | D9: 0.15 | E9: 3.308 | F9: 6.262
A10: Palo | B10: Desembocadura a río Cauca | C10: 3 | D10: 3.492 | E10: 5.117 | F10: 5.728
A11: Palo | B11: Después de PTAR Guachené | C11: 12 | D11: 0 | E11: 14.016 | F11: 12606
A12: Palo | B12: Puente PICC | C12: 6 | D12: 4.609 | E12: 22.27 | F12: 58.04
A13: Palo | B13: Puente Perico Negro | C13: 3 | D13: 0 | E13: 3.21 | F13: 21.25
A14: Palo | B14: Puente Puerto Tejada | C14: 7 | D14: 0 | E14: 25.02 | F14: 159
A15: Palo | B15: Puente del Maíz | C15: 5 | D15: 0 | E15: 19.45 | F15: 23.29
A16: Risaralda | B16: Quebrada Chapata - Desembocadura | C16: 45 | D16: 448 | E16: 2511 | F16: 9291
... A22: Risaralda | B22: Río Risaralda - Puente Umbría | C22: 44 | D22: 0 | E22: 5751.5 | F22: 17875
A24: Cobertura | B24: De los 15 tributarios priorizados, solo tres registran caudal: Palo y Desbaratado (CRC) y Risaralda (CARDER). Los doce ríos monitoreados por la CVC en el Valle del Cauca —incluidos Bolo, Fraile, Amaime, Guabas, Tuluá, Zabaletas y los demás— tienen la columna de caudal completamente vacía en las 1.567 filas del archivo.
A25: Muestras utilizables | B25: Cruzando caudal con nutrientes en la misma muestra quedan 52 registros con N y caudal y 64 con P y caudal, sobre 1.567 filas. En Risaralda, que es el río con más caudales (217), solo un registro tiene además nutrientes.
A26: Unidades inconsistentes | B26: En Palo y Desbaratado los valores de una misma estación van de 0,00 a más de 13.000 con el encabezado "Caudal (l/s)". La estación "Antes de PTAR Guachené" tiene mediana 12,44 y máximo 13.122: la columna mezcla lecturas en m³/s con lecturas en L/s. Usarlas sin depurar produciría cargas erradas en tres órdenes de magnitud.
A27: Ceros imposibles | B27: Varias estaciones registran caudal 0,00 en ríos permanentes. Son datos faltantes codificados como cero, no caudales reales; entrarían al cálculo como carga nula.
A28: Qué se necesita | B28: Series de caudal de las estaciones limnigráficas de la CVC emparejadas por fecha con cada campaña de calidad, en unidad declarada y sin ceros de relleno. Con eso, la conversión a kg/día y el porcentaje de carga atribuible a la caña quedan resueltos con las fórmulas que ya están montadas.
